<?xml version="1.0"?>
<robot xmlns:xacro="http://www.ros.org/wiki/xacro" name="diffbot">

    <xacro:include filename="$(find diffbot)/urdf/materials.xacro"/>
    <xacro:include filename="$(find diffbot)/urdf/inertia.xacro"/>
    <xacro:include filename="$(find diffbot)/urdf/gazebo.xacro"/>

    <link name="base_footprint"/>

    <link name="base_link"/>

    <joint name="base_joint" type="fixed">
        <parent link="base_footprint"/>
        <child link="base_link"/>
        <origin xyz="0 0 0" rpy="0 0 0.0" />
    </joint>

    <link name="chassis_link">

        <collision>
            <origin xyz="0 0 0" rpy="0 0 0" />
            <geometry>
                <box size="1.0 1.5 0.3"/>
            </geometry>
        </collision>

        <visual>
            <origin xyz="0 0 0" rpy="0 0 0" />
            <geometry>
                <mesh filename="file://$(find diffbot)/meshes/body_nokiya.dae" scale="1 1 1"/>
            </geometry>
        </visual>

        <inertial>
            <mass value="1.0" />
            <xacro:box_inertia m="1.0" x="1.0" y="1.5" z = "0.3"/>
        </inertial>

    </link>

    <joint name="chassis_joint" type="fixed">
        <parent link="base_link"/>
        <child link="chassis_link"/>
        <origin xyz="0.0 0 0" rpy="0 0 0.0" />
    </joint>

    <!-- Left Wheels -->
    <link name="left_wheel">

        <collision>
            <origin xyz="0 0 0" rpy="1.57 0 0" />
            <geometry>
                <cylinder radius="0.2" length="0.1"/>
            </geometry>
        </collision>

        <visual>
            <origin xyz="0 0 0" rpy="1.57 0 0" />
            <geometry>
                <cylinder radius="0.2" length="0.1"/> 
            </geometry>
        </visual>

        <inertial>
            <mass value="0.5"/>
            <xacro:cylinder_inertia m="0.5" r="-0.2" h="0.1"/>
        </inertial>

    </link>

    <joint name="left_wheel_joint" type="continuous">
        <parent link="chassis_link"/>
        <child link="left_wheel"/>
        <origin xyz="0.0 0.55 -0.07" rpy="0 0 0" />
        <axis xyz="0.0 1.0 0.0"/>
    </joint>

    <!-- Right Wheels -->
    <link name="right_wheel">

        <collision>
            <origin xyz="0 0 0" rpy="1.57 0 0" />
            <geometry>
                <cylinder radius="0.2" length="0.1"/>
            </geometry>
        </collision>

        <visual>
            <origin xyz="0 0 0" rpy="1.57 0 0" />
            <geometry>
                <cylinder radius="0.2" length="0.1"/> 
            </geometry>
        </visual>

        <inertial>
            <mass value="0.5"/>
            <xacro:cylinder_inertia m="0.5" r="-0.2" h="0.1"/>
        </inertial>

    </link>

    <joint name="right_wheel_joint" type="continuous"> 
        <parent link="chassis_link"/>
        <child link="right_wheel"/>
        <origin xyz="0.0 -0.55 -0.07" rpy="0 0 0" />
        <axis xyz="0.0 1.0 0.0"/>
    </joint>

    <gazebo reference="left_wheel">
        <material>Gazebo/Black</material>
    </gazebo>

    <gazebo reference="right_wheel">
        <material>Gazebo/Black</material>
    </gazebo>

        <!-- Caster Wheel Front -->
    <link name="front_yaw_link">
        <visual>
            <origin rpy="0 1.5707 1.5707" xyz="0 0 0"/>
            <geometry>
              <cylinder length="0.005" radius="0.17"/>
            </geometry>
            <material name="wooden"/>
        </visual>

        <collision>
            <origin rpy="0 1.5707 1.5707" xyz="0 0 0"/>
            <geometry>
                <cylinder length="0.005" radius="0.17"/>
            </geometry>
        </collision>

        <inertial>
            <origin rpy="0 1.5707 1.5707" xyz="0 0 0"/>
            <mass value="0.001"/>
            <inertia ixx="4.020833333333333e-07" ixy="0" ixz="0" iyy="4.020833333333333e-07" iyz="0" izz="8.000000000000001e-07"/>
        </inertial>
    </link>

    <joint name="front_yaw_joint" type="continuous">
        <origin rpy="0 0 0" xyz="0.5 0 -0.1"/>
        <parent link="chassis_link" />
        <child link="front_yaw_link" />
        <axis xyz="0 0 1" />
        <limit effort="1000.0" velocity="100.0" />
        <dynamics damping="0.0" friction="0.1"/>
    </joint>

    <gazebo reference="front_yaw_link">
        <material>Gazebo/Purple</material>
    </gazebo>

    <link name="front_roll_link">
        <visual>
            <origin rpy="0 1.5707 1.5707" xyz="0 0 0"/>
            <geometry>
                <cylinder length="0.005" radius="0.17"/>
            </geometry>
            <material name="wooden"/>
        </visual>

        <collision>
            <origin rpy="0 1.5707 1.5707" xyz="0 0 0"/>
            <geometry>
                <cylinder length="0.005" radius="0.17"/>
            </geometry>
        </collision>

        <inertial>
            <origin rpy="0 1.5707 1.5707" xyz="0 0 0"/>
            <mass value="0.001"/>
            <inertia ixx="4.020833333333333e-07" ixy="0" ixz="0" iyy="4.020833333333333e-07" iyz="0" izz="8.000000000000001e-07"/>
        </inertial>
    </link>

    <joint name="front_roll_joint" type="continuous">
        <origin rpy="0 0 0" xyz="0 0 0" />
        <parent link="front_yaw_link" />
        <child link="front_roll_link" />
        <axis xyz="1 0 0" />
        <limit effort="1000.0" velocity="100.0" />
        <dynamics damping="0.0" friction="0.1"/>
    </joint>
        
    <gazebo reference="front_roll_link">
        <material>Gazebo/Purple</material>
    </gazebo>

    <link name="front_pitch_link">
        <visual>
            <origin rpy="0 1.5707 1.5707" xyz="0 0 0"/>
            <geometry>
                <sphere radius="0.17"/>
            </geometry>
            <material name="wooden"/>
        </visual>

        <collision>
            <origin rpy="0 1.5707 1.5707" xyz="0 0 0"/>
            <geometry>
                <sphere radius="0.17"/>
            </geometry>
        </collision>

        <inertial>
            <origin rpy="0 1.5707 1.5707" xyz="0 0 0"/>
            <mass value="0.001"/>
            <inertia ixx="6.4e-07" ixy="0" ixz="0" iyy="6.4e-07" iyz="0" izz="6.4e-07"/>
        </inertial>
    </link>

    <gazebo reference="front_pitch_link">
        <kp>100000000000000.0</kp>
        <kd>100000000000000.0</kd>
        <mu1>0.5</mu1>
        <mu2>0.5</mu2>
        <material>Gazebo/Purple</material>
    </gazebo>

    <joint name="front_pitch_joint" type="continuous">
        <origin rpy="0 0 0" xyz="0 0 0" />
        <parent link="front_roll_link" />
        <child link="front_pitch_link" />
        <axis xyz="0 1 0" />
        <limit effort="1000.0" velocity="100.0" />
        <dynamics damping="0.0" friction="0.1"/>
    </joint>

    <!-- Caster Wheel Back -->
    <link name="back_yaw_link">
        <visual>
            <origin rpy="0 1.5707 1.5707" xyz="0 0 0"/>
            <geometry>
              <cylinder length="0.005" radius="0.17"/>
            </geometry>
            <material name="wooden"/>
        </visual>

        <collision>
            <origin rpy="0 1.5707 1.5707" xyz="0 0 0"/>
            <geometry>
                <cylinder length="0.005" radius="0.17"/>
            </geometry>
        </collision>

        <inertial>
            <origin rpy="0 1.5707 1.5707" xyz="0 0 0"/>
            <mass value="0.001"/>
            <inertia ixx="4.020833333333333e-07" ixy="0" ixz="0" iyy="4.020833333333333e-07" iyz="0" izz="8.000000000000001e-07"/>
        </inertial>
    </link>

    <joint name="back_yaw_joint" type="continuous">
        <origin rpy="0 0 0" xyz="-0.5 0 -0.1"/>
        <parent link="chassis_link" />
        <child link="back_yaw_link" />
        <axis xyz="0 0 1" />
        <limit effort="1000.0" velocity="100.0" />
        <dynamics damping="0.0" friction="0.1"/>
    </joint>

    <gazebo reference="back_yaw_link">
        <material>Gazebo/Purple</material>
    </gazebo>

    <link name="back_roll_link">
        <visual>
            <origin rpy="0 1.5707 1.5707" xyz="0 0 0"/>
            <geometry>
                <cylinder length="0.005" radius="0.17"/>
            </geometry>
            <material name="wooden"/>
        </visual>

        <collision>
            <origin rpy="0 1.5707 1.5707" xyz="0 0 0"/>
            <geometry>
                <cylinder length="0.005" radius="0.17"/>
            </geometry>
        </collision>

        <inertial>
            <origin rpy="0 1.5707 1.5707" xyz="0 0 0"/>
            <mass value="0.001"/>
            <inertia ixx="4.020833333333333e-07" ixy="0" ixz="0" iyy="4.020833333333333e-07" iyz="0" izz="8.000000000000001e-07"/>
        </inertial>
    </link>

    <joint name="back_roll_joint" type="continuous">
        <origin rpy="0 0 0" xyz="0 0 0"/>
        <parent link="back_yaw_link"/>
        <child link="back_roll_link"/>
        <axis xyz="1 0 0" />
        <limit effort="1000.0" velocity="100.0" />
        <dynamics damping="0.0" friction="0.1"/>
    </joint>
        
    <gazebo reference="back_roll_link">
        <material>Gazebo/Purple</material>
    </gazebo>

    <link name="back_pitch_link">
        <visual>
            <origin rpy="0 1.5707 1.5707" xyz="0 0 0"/>
            <geometry>
                <sphere radius="0.17"/>
            </geometry>
            <material name="wooden"/>
        </visual>

        <collision>
            <origin rpy="0 1.5707 1.5707" xyz="0 0 0"/>
            <geometry>
                <sphere radius="0.17"/>
            </geometry>
        </collision>

        <inertial>
            <origin rpy="0 1.5707 1.5707" xyz="0 0 0"/>
            <mass value="0.001"/>
            <inertia ixx="6.4e-07" ixy="0" ixz="0" iyy="6.4e-07" iyz="0" izz="6.4e-07"/>
        </inertial>
    </link>

    <gazebo reference="back_pitch_link">
        <kp>100000000000000.0</kp>
        <kd>100000000000000.0</kd>
        <mu1>0.5</mu1>
        <mu2>0.5</mu2>
        <material>Gazebo/Purple</material>
    </gazebo>

    <joint name="back_pitch_joint" type="continuous">
        <origin rpy="0 0 0" xyz="0 0 0" />
        <parent link="back_roll_link" />
        <child link="back_pitch_link" />
        <axis xyz="0 1 0" />
        <limit effort="1000.0" velocity="100.0" />
        <dynamics damping="0.0" friction="0.1"/>
    </joint>

    <!-- ............................. 2D LIDAR ........................................ -->

    <!-- <xacro:if value="$(arg two_d_lidar_enabled)"> -->

    <link name="two_d_lidar">
        <collision>
            <origin xyz="0 0 0" rpy="0 0 0" />
            <geometry>
                <cylinder length="0.06" radius="0.075"/>
            </geometry>
        </collision>

        <visual>
            <origin xyz="0 0 0" rpy="0 0 0" />
            <geometry>
                <cylinder length="0.06" radius="0.075"/>
            </geometry>
            <material name="aluminium"/>
        </visual>

        <inertial>
            <origin xyz="0 0 0" rpy="0 0 0" />
            <mass value="0.1"/>
            <xacro:cylinder_inertia m="0.1" r="0.075" h="0.06"/>
        </inertial>
    </link>

    <joint name="two_d_lidar_joint" type="fixed">
        <parent link="chassis_link"/>
        <child link="two_d_lidar"/>
        <origin xyz="0.0 0 0.16" rpy="0 0 0" />
    </joint>

    <gazebo reference="two_d_lidar">
        <material>Gazebo/White</material>
    </gazebo>


    <!-- ............................. IMU ....................
    .................... -->

    <link name="imu_frame"/>

    <joint name="imu_joint" type="fixed">
        <parent link="base_link"/>
        <child link="imu_frame"/>
        <origin xyz="0.0 0.0 0.16" rpy="0.0 0.0 0.0"/>
    </joint>

</robot>